Traceback (most recent call last):
  File "/home/yanw/.conda/envs/uncertain/lib/python3.9/site-packages/jax/_src/lax/lax.py", line 149, in broadcast_shapes
    return _broadcast_shapes_cached(*shapes)
  File "/home/yanw/.conda/envs/uncertain/lib/python3.9/site-packages/jax/_src/util.py", line 287, in wrapper
    return cached(config.trace_context(), *args, **kwargs)
  File "/home/yanw/.conda/envs/uncertain/lib/python3.9/site-packages/jax/_src/util.py", line 280, in cached
    return f(*args, **kwargs)
  File "/home/yanw/.conda/envs/uncertain/lib/python3.9/site-packages/jax/_src/lax/lax.py", line 155, in _broadcast_shapes_cached
    return _broadcast_shapes_uncached(*shapes)
  File "/home/yanw/.conda/envs/uncertain/lib/python3.9/site-packages/jax/_src/lax/lax.py", line 171, in _broadcast_shapes_uncached
    raise ValueError(f"Incompatible shapes for broadcasting: shapes={list(shapes)}")
ValueError: Incompatible shapes for broadcasting: shapes=[(), (2, 1), (5, 5)]

During handling of the above exception, another exception occurred:

Traceback (most recent call last):
  File "/local/293398/main.py", line 126, in <module>
    mcmc = run_mcmc(Xu_fixed, Xf, Y, Xu_noise, jnp.eye(number_u) * prior_var, param_iter, num_samples=num_samples,
  File "/local/293398/include/mcmc_posterior.py", line 60, in run_mcmc
    mcmc.run(rng_key, Xfz, Xfg, Y_data, prior_mean, prior_cov, init_params)
  File "/home/yanw/.conda/envs/uncertain/lib/python3.9/site-packages/numpyro/infer/mcmc.py", line 666, in run
    states_flat, last_state = partial_map_fn(map_args)
  File "/home/yanw/.conda/envs/uncertain/lib/python3.9/site-packages/numpyro/infer/mcmc.py", line 438, in _single_chain_mcmc
    new_init_state = self.sampler.init(
  File "/home/yanw/.conda/envs/uncertain/lib/python3.9/site-packages/numpyro/infer/hmc.py", line 749, in init
    init_params = self._init_state(
  File "/home/yanw/.conda/envs/uncertain/lib/python3.9/site-packages/numpyro/infer/hmc.py", line 693, in _init_state
    ) = initialize_model(
  File "/home/yanw/.conda/envs/uncertain/lib/python3.9/site-packages/numpyro/infer/util.py", line 656, in initialize_model
    ) = _get_model_transforms(substituted_model, model_args, model_kwargs)
  File "/home/yanw/.conda/envs/uncertain/lib/python3.9/site-packages/numpyro/infer/util.py", line 450, in _get_model_transforms
    model_trace = trace(model).get_trace(*model_args, **model_kwargs)
  File "/home/yanw/.conda/envs/uncertain/lib/python3.9/site-packages/numpyro/handlers.py", line 171, in get_trace
    self(*args, **kwargs)
  File "/home/yanw/.conda/envs/uncertain/lib/python3.9/site-packages/numpyro/primitives.py", line 105, in __call__
    return self.fn(*args, **kwargs)
  File "/home/yanw/.conda/envs/uncertain/lib/python3.9/site-packages/numpyro/primitives.py", line 105, in __call__
    return self.fn(*args, **kwargs)
  File "/home/yanw/.conda/envs/uncertain/lib/python3.9/site-packages/numpyro/primitives.py", line 105, in __call__
    return self.fn(*args, **kwargs)
  File "/local/293398/include/mcmc_posterior.py", line 37, in model
    dist.MultivariateNormal(prior_mean[num_sample, :], covariance_matrix=prior_cov))
  File "/home/yanw/.conda/envs/uncertain/lib/python3.9/site-packages/numpyro/distributions/distribution.py", line 99, in __call__
    return super().__call__(*args, **kwargs)
  File "/home/yanw/.conda/envs/uncertain/lib/python3.9/site-packages/numpyro/distributions/continuous.py", line 1502, in __init__
    loc, self.covariance_matrix = promote_shapes(loc, covariance_matrix)
  File "/home/yanw/.conda/envs/uncertain/lib/python3.9/site-packages/numpyro/distributions/util.py", line 309, in promote_shapes
    num_dims = len(lax.broadcast_shapes(shape, *shapes))
  File "/home/yanw/.conda/envs/uncertain/lib/python3.9/site-packages/jax/_src/lax/lax.py", line 151, in broadcast_shapes
    return _broadcast_shapes_uncached(*shapes)
  File "/home/yanw/.conda/envs/uncertain/lib/python3.9/site-packages/jax/_src/lax/lax.py", line 171, in _broadcast_shapes_uncached
    raise ValueError(f"Incompatible shapes for broadcasting: shapes={list(shapes)}")
ValueError: Incompatible shapes for broadcasting: shapes=[(), (2, 1), (5, 5)]
--------------------------------------------------------------------------
Primary job  terminated normally, but 1 process returned
a non-zero exit code. Per user-direction, the job has been aborted.
--------------------------------------------------------------------------
--------------------------------------------------------------------------
mpirun detected that one or more processes exited with non-zero status, thus causing
the job to be terminated. The first process to do so was:

  Process name: [[30229,1],0]
  Exit code:    1
--------------------------------------------------------------------------
cp: missing destination file operand after '*.png/home/yanw/uncertain/results/figures/0614'
Try 'cp --help' for more information.
cp: missing destination file operand after '/home/yanw/uncertain'
Try 'cp --help' for more information.
mv: cannot stat '*.log': No such file or directory
