	Adding nVidia Cuda Toolkit 11.8
	Adding nVidia cuDNN 8.6 (.0.163)

CondaHTTPError: HTTP 000 CONNECTION FAILED for url <https://conda.anaconda.org/conda-forge/linux-64/current_repodata.json>
Elapsed: -

An HTTP error occurred when trying to retrieve this URL.
HTTP errors are often intermittent, and a simple retry will get you on your way.
'https://conda.anaconda.org/conda-forge/linux-64'


Traceback (most recent call last):
  File "/home/yanw/.local/lib/python3.9/site-packages/pytensor/configparser.py", line 201, in fetch_val_for_key
    return self._pytensor_cfg.get(section, option)
  File "/home/yanw/.conda/envs/uncert/lib/python3.9/configparser.py", line 781, in get
    d = self._unify_values(section, vars)
  File "/home/yanw/.conda/envs/uncert/lib/python3.9/configparser.py", line 1152, in _unify_values
    raise NoSectionError(section) from None
configparser.NoSectionError: No section: 'blas'

During handling of the above exception, another exception occurred:

Traceback (most recent call last):
  File "/home/yanw/.local/lib/python3.9/site-packages/pytensor/configparser.py", line 317, in __get__
    val_str = cls.fetch_val_for_key(self.name, delete_key=delete_key)
  File "/home/yanw/.local/lib/python3.9/site-packages/pytensor/configparser.py", line 205, in fetch_val_for_key
    raise KeyError(key)
KeyError: 'blas__ldflags'

During handling of the above exception, another exception occurred:

Traceback (most recent call last):
  File "/local/239242/main.py", line 5, in <module>
    from include.mcmc_posterior import Metropolis_Hasting
  File "/local/239242/include/mcmc_posterior.py", line 5, in <module>
    import pymc as pm
  File "/home/yanw/.local/lib/python3.9/site-packages/pymc/__init__.py", line 47, in <module>
    __set_compiler_flags()
  File "/home/yanw/.local/lib/python3.9/site-packages/pymc/__init__.py", line 30, in __set_compiler_flags
    import pytensor
  File "/home/yanw/.local/lib/python3.9/site-packages/pytensor/__init__.py", line 119, in <module>
    from pytensor import scalar, tensor
  File "/home/yanw/.local/lib/python3.9/site-packages/pytensor/tensor/__init__.py", line 106, in <module>
    from pytensor.tensor import (  # noqa
  File "/home/yanw/.local/lib/python3.9/site-packages/pytensor/tensor/blas.py", line 102, in <module>
    from pytensor.tensor.blas_headers import blas_header_text, blas_header_version
  File "/home/yanw/.local/lib/python3.9/site-packages/pytensor/tensor/blas_headers.py", line 1015, in <module>
    if not config.blas__ldflags:
  File "/home/yanw/.local/lib/python3.9/site-packages/pytensor/configparser.py", line 321, in __get__
    val_str = self.default()
  File "/home/yanw/.local/lib/python3.9/site-packages/pytensor/link/c/cmodule.py", line 2720, in default_blas_ldflags
    blas_info = np.__config__.get_info("blas_opt")
AttributeError: module 'numpy.__config__' has no attribute 'get_info'
--------------------------------------------------------------------------
Primary job  terminated normally, but 1 process returned
a non-zero exit code. Per user-direction, the job has been aborted.
--------------------------------------------------------------------------
--------------------------------------------------------------------------
mpirun detected that one or more processes exited with non-zero status, thus causing
the job to be terminated. The first process to do so was:

  Process name: [[15353,1],0]
  Exit code:    1
--------------------------------------------------------------------------
cp: missing destination file operand after '*.png/home/yanw/uncertain/results/figures/1007'
Try 'cp --help' for more information.
cp: missing destination file operand after '/home/yanw/uncertain'
Try 'cp --help' for more information.
