Traceback (most recent call last):
  File "/local/293690/main.py", line 184, in <module>
    plt.plot(Xu_fixed[0], Yu_fixed, 'bs', label='True values')
  File "/home/yanw/.conda/envs/uncertain/lib/python3.9/site-packages/matplotlib/pyplot.py", line 2812, in plot
    return gca().plot(
  File "/home/yanw/.conda/envs/uncertain/lib/python3.9/site-packages/matplotlib/axes/_axes.py", line 1688, in plot
    lines = [*self._get_lines(*args, data=data, **kwargs)]
  File "/home/yanw/.conda/envs/uncertain/lib/python3.9/site-packages/matplotlib/axes/_base.py", line 311, in __call__
    yield from self._plot_args(
  File "/home/yanw/.conda/envs/uncertain/lib/python3.9/site-packages/matplotlib/axes/_base.py", line 504, in _plot_args
    raise ValueError(f"x and y must have same first dimension, but "
ValueError: x and y must have same first dimension, but have shapes (2,) and (15, 1)
--------------------------------------------------------------------------
Primary job  terminated normally, but 1 process returned
a non-zero exit code. Per user-direction, the job has been aborted.
--------------------------------------------------------------------------
--------------------------------------------------------------------------
mpirun detected that one or more processes exited with non-zero status, thus causing
the job to be terminated. The first process to do so was:

  Process name: [[21805,1],0]
  Exit code:    1
--------------------------------------------------------------------------
cp: missing destination file operand after '*.png/home/yanw/uncertain/results/figures/0617'
Try 'cp --help' for more information.
cp: missing destination file operand after '/home/yanw/uncertain'
Try 'cp --help' for more information.
mv: cannot stat '*.log': No such file or directory
